2021-06-18 16:41:03,205 8606440960     INFO test_runner.py(156) - 预计并发线程数：1
2021-06-18 16:41:15,527 12949573632     INFO result.py(69) - 开始测试： test_click_aboutUs (test.test_firstp.TestFirstp005)
2021-06-18 16:41:28,989 12949573632  WARNING result.py(190) - 测试未通过： test_click_aboutUs (test.test_firstp.TestFirstp005)
Traceback (most recent call last):
  File "/Users/yuanyuanhe/PycharmProjects/zspaimai_ui/test/test_firstp.py", line 172, in test_click_aboutUs
    self.assertEqual('http://home.online.zspaimai.cn/article?keywords=about_us', self.driver.current_url)
AssertionError: 'http://home.online.zspaimai.cn/article?keywords=about_us' != 'http://home.online.zspaimai.cn/'
- http://home.online.zspaimai.cn/article?keywords=about_us
+ http://home.online.zspaimai.cn/


2021-06-18 16:41:29,001 12949573632     INFO result.py(90) - 测试结束： test_click_aboutUs (test.test_firstp.TestFirstp005)
2021-06-18 16:41:29,001 12949573632     INFO result.py(91) - 耗时： 13.473284006118774
2021-06-18 16:41:29,008 12949573632     INFO result.py(69) - 开始测试： test_click_biddingInfo (test.test_firstp.TestFirstp005)
2021-06-18 16:41:42,709 12949573632     INFO result.py(156) - 测试执行通过： test_click_biddingInfo (test.test_firstp.TestFirstp005)
2021-06-18 16:41:42,716 12949573632     INFO result.py(90) - 测试结束： test_click_biddingInfo (test.test_firstp.TestFirstp005)
2021-06-18 16:41:42,722 12949573632     INFO result.py(91) - 耗时： 13.708050012588501
2021-06-18 16:41:42,729 12949573632     INFO result.py(69) - 开始测试： test_click_collectionGuarantee (test.test_firstp.TestFirstp005)
2021-06-18 16:41:55,961 12949573632     INFO result.py(156) - 测试执行通过： test_click_collectionGuarantee (test.test_firstp.TestFirstp005)
2021-06-18 16:41:55,961 12949573632     INFO result.py(90) - 测试结束： test_click_collectionGuarantee (test.test_firstp.TestFirstp005)
2021-06-18 16:41:55,967 12949573632     INFO result.py(91) - 耗时： 13.23223328590393
2021-06-18 16:41:55,973 12949573632     INFO result.py(69) - 开始测试： test_click_contactUs (test.test_firstp.TestFirstp005)
2021-06-18 16:42:12,536 12949573632     INFO result.py(156) - 测试执行通过： test_click_contactUs (test.test_firstp.TestFirstp005)
2021-06-18 16:42:12,543 12949573632     INFO result.py(90) - 测试结束： test_click_contactUs (test.test_firstp.TestFirstp005)
2021-06-18 16:42:12,543 12949573632     INFO result.py(91) - 耗时： 16.569956064224243
2021-06-18 16:42:12,550 12949573632     INFO result.py(69) - 开始测试： test_click_guide (test.test_firstp.TestFirstp005)
2021-06-18 16:42:15,577 12949573632  WARNING connectionpool.py(780) - Retrying (Retry(total=2, connect=None, read=None, redirect=None, status=None)) after connection broken by 'NewConnectionError('<urllib3.connection.HTTPConnection object at 0x10afcde20>: Failed to establish a new connection: [Errno 61] Connection refused')': /session/af66b1ad69a271d151e2b397b69d8951/url
2021-06-18 16:42:15,597 12949573632  WARNING connectionpool.py(780) - Retrying (Retry(total=1, connect=None, read=None, redirect=None, status=None)) after connection broken by 'NewConnectionError('<urllib3.connection.HTTPConnection object at 0x10afe2fd0>: Failed to establish a new connection: [Errno 61] Connection refused')': /session/af66b1ad69a271d151e2b397b69d8951/url
2021-06-18 16:42:15,616 12949573632  WARNING connectionpool.py(780) - Retrying (Retry(total=0, connect=None, read=None, redirect=None, status=None)) after connection broken by 'NewConnectionError('<urllib3.connection.HTTPConnection object at 0x10b1d0040>: Failed to establish a new connection: [Errno 61] Connection refused')': /session/af66b1ad69a271d151e2b397b69d8951/url
2021-06-18 16:42:15,961 12949573632    ERROR result.py(175) - 测试产生错误： test_click_guide (test.test_firstp.TestFirstp005)
Traceback (most recent call last):
  File "/Users/yuanyuanhe/PycharmProjects/zspaimai_ui/venv/lib/python3.9/site-packages/urllib3/connection.py", line 169, in _new_conn
    conn = connection.create_connection(
  File "/Users/yuanyuanhe/PycharmProjects/zspaimai_ui/venv/lib/python3.9/site-packages/urllib3/util/connection.py", line 96, in create_connection
    raise err
  File "/Users/yuanyuanhe/PycharmProjects/zspaimai_ui/venv/lib/python3.9/site-packages/urllib3/util/connection.py", line 86, in create_connection
    sock.connect(sa)
ConnectionRefusedError: [Errno 61] Connection refused

During handling of the above exception, another exception occurred:

Traceback (most recent call last):
  File "/Users/yuanyuanhe/PycharmProjects/zspaimai_ui/venv/lib/python3.9/site-packages/urllib3/connectionpool.py", line 699, in urlopen
    httplib_response = self._make_request(
  File "/Users/yuanyuanhe/PycharmProjects/zspaimai_ui/venv/lib/python3.9/site-packages/urllib3/connectionpool.py", line 394, in _make_request
    conn.request(method, url, **httplib_request_kw)
  File "/Users/yuanyuanhe/PycharmProjects/zspaimai_ui/venv/lib/python3.9/site-packages/urllib3/connection.py", line 234, in request
    super(HTTPConnection, self).request(method, url, body=body, headers=headers)
  File "/Library/Frameworks/Python.framework/Versions/3.9/lib/python3.9/http/client.py", line 1253, in request
    self._send_request(method, url, body, headers, encode_chunked)
  File "/Library/Frameworks/Python.framework/Versions/3.9/lib/python3.9/http/client.py", line 1299, in _send_request
    self.endheaders(body, encode_chunked=encode_chunked)
  File "/Library/Frameworks/Python.framework/Versions/3.9/lib/python3.9/http/client.py", line 1248, in endheaders
    self._send_output(message_body, encode_chunked=encode_chunked)
  File "/Library/Frameworks/Python.framework/Versions/3.9/lib/python3.9/http/client.py", line 1008, in _send_output
    self.send(msg)
  File "/Library/Frameworks/Python.framework/Versions/3.9/lib/python3.9/http/client.py", line 948, in send
    self.connect()
  File "/Users/yuanyuanhe/PycharmProjects/zspaimai_ui/venv/lib/python3.9/site-packages/urllib3/connection.py", line 200, in connect
    conn = self._new_conn()
  File "/Users/yuanyuanhe/PycharmProjects/zspaimai_ui/venv/lib/python3.9/site-packages/urllib3/connection.py", line 181, in _new_conn
    raise NewConnectionError(
urllib3.exceptions.NewConnectionError: <urllib3.connection.HTTPConnection object at 0x10b1d0160>: Failed to establish a new connection: [Errno 61] Connection refused

During handling of the above exception, another exception occurred:

Traceback (most recent call last):
  File "/Users/yuanyuanhe/PycharmProjects/zspaimai_ui/test/init.py", line 44, in setUp
    self.driver.get(url)
  File "/Users/yuanyuanhe/PycharmProjects/zspaimai_ui/venv/lib/python3.9/site-packages/selenium/webdriver/remote/webdriver.py", line 333, in get
    self.execute(Command.GET, {'url': url})
  File "/Users/yuanyuanhe/PycharmProjects/zspaimai_ui/venv/lib/python3.9/site-packages/selenium/webdriver/remote/webdriver.py", line 319, in execute
    response = self.command_executor.execute(driver_command, params)
  File "/Users/yuanyuanhe/PycharmProjects/zspaimai_ui/venv/lib/python3.9/site-packages/selenium/webdriver/remote/remote_connection.py", line 374, in execute
    return self._request(command_info[0], url, body=data)
  File "/Users/yuanyuanhe/PycharmProjects/zspaimai_ui/venv/lib/python3.9/site-packages/selenium/webdriver/remote/remote_connection.py", line 397, in _request
    resp = self._conn.request(method, url, body=body, headers=headers)
  File "/Users/yuanyuanhe/PycharmProjects/zspaimai_ui/venv/lib/python3.9/site-packages/urllib3/request.py", line 78, in request
    return self.request_encode_body(
  File "/Users/yuanyuanhe/PycharmProjects/zspaimai_ui/venv/lib/python3.9/site-packages/urllib3/request.py", line 170, in request_encode_body
    return self.urlopen(method, url, **extra_kw)
  File "/Users/yuanyuanhe/PycharmProjects/zspaimai_ui/venv/lib/python3.9/site-packages/urllib3/poolmanager.py", line 375, in urlopen
    response = conn.urlopen(method, u.request_uri, **kw)
  File "/Users/yuanyuanhe/PycharmProjects/zspaimai_ui/venv/lib/python3.9/site-packages/urllib3/connectionpool.py", line 783, in urlopen
    return self.urlopen(
  File "/Users/yuanyuanhe/PycharmProjects/zspaimai_ui/venv/lib/python3.9/site-packages/urllib3/connectionpool.py", line 783, in urlopen
    return self.urlopen(
  File "/Users/yuanyuanhe/PycharmProjects/zspaimai_ui/venv/lib/python3.9/site-packages/urllib3/connectionpool.py", line 783, in urlopen
    return self.urlopen(
  File "/Users/yuanyuanhe/PycharmProjects/zspaimai_ui/venv/lib/python3.9/site-packages/urllib3/connectionpool.py", line 755, in urlopen
    retries = retries.increment(
  File "/Users/yuanyuanhe/PycharmProjects/zspaimai_ui/venv/lib/python3.9/site-packages/urllib3/util/retry.py", line 574, in increment
    raise MaxRetryError(_pool, url, error or ResponseError(cause))
urllib3.exceptions.MaxRetryError: HTTPConnectionPool(host='127.0.0.1', port=63005): Max retries exceeded with url: /session/af66b1ad69a271d151e2b397b69d8951/url (Caused by NewConnectionError('<urllib3.connection.HTTPConnection object at 0x10b1d0160>: Failed to establish a new connection: [Errno 61] Connection refused'))

2021-06-18 16:42:15,967 12949573632     INFO result.py(90) - 测试结束： test_click_guide (test.test_firstp.TestFirstp005)
2021-06-18 16:42:15,973 12949573632     INFO result.py(91) - 耗时： 3.4170031547546387
2021-06-18 16:42:15,980 12949573632     INFO result.py(69) - 开始测试： test_click_serviceA (test.test_firstp.TestFirstp005)
2021-06-18 16:42:18,989 12949573632  WARNING connectionpool.py(780) - Retrying (Retry(total=2, connect=None, read=None, redirect=None, status=None)) after connection broken by 'NewConnectionError('<urllib3.connection.HTTPConnection object at 0x10b1d0370>: Failed to establish a new connection: [Errno 61] Connection refused')': /session/af66b1ad69a271d151e2b397b69d8951/url
2021-06-18 16:42:18,991 12949573632  WARNING connectionpool.py(780) - Retrying (Retry(total=1, connect=None, read=None, redirect=None, status=None)) after connection broken by 'NewConnectionError('<urllib3.connection.HTTPConnection object at 0x10b1d08b0>: Failed to establish a new connection: [Errno 61] Connection refused')': /session/af66b1ad69a271d151e2b397b69d8951/url
2021-06-18 16:42:18,992 12949573632  WARNING connectionpool.py(780) - Retrying (Retry(total=0, connect=None, read=None, redirect=None, status=None)) after connection broken by 'NewConnectionError('<urllib3.connection.HTTPConnection object at 0x10b1d0a30>: Failed to establish a new connection: [Errno 61] Connection refused')': /session/af66b1ad69a271d151e2b397b69d8951/url
2021-06-18 16:42:18,996 12949573632    ERROR result.py(175) - 测试产生错误： test_click_serviceA (test.test_firstp.TestFirstp005)
Traceback (most recent call last):
  File "/Users/yuanyuanhe/PycharmProjects/zspaimai_ui/venv/lib/python3.9/site-packages/urllib3/connection.py", line 169, in _new_conn
    conn = connection.create_connection(
  File "/Users/yuanyuanhe/PycharmProjects/zspaimai_ui/venv/lib/python3.9/site-packages/urllib3/util/connection.py", line 96, in create_connection
    raise err
  File "/Users/yuanyuanhe/PycharmProjects/zspaimai_ui/venv/lib/python3.9/site-packages/urllib3/util/connection.py", line 86, in create_connection
    sock.connect(sa)
ConnectionRefusedError: [Errno 61] Connection refused

During handling of the above exception, another exception occurred:

Traceback (most recent call last):
  File "/Users/yuanyuanhe/PycharmProjects/zspaimai_ui/venv/lib/python3.9/site-packages/urllib3/connectionpool.py", line 699, in urlopen
    httplib_response = self._make_request(
  File "/Users/yuanyuanhe/PycharmProjects/zspaimai_ui/venv/lib/python3.9/site-packages/urllib3/connectionpool.py", line 394, in _make_request
    conn.request(method, url, **httplib_request_kw)
  File "/Users/yuanyuanhe/PycharmProjects/zspaimai_ui/venv/lib/python3.9/site-packages/urllib3/connection.py", line 234, in request
    super(HTTPConnection, self).request(method, url, body=body, headers=headers)
  File "/Library/Frameworks/Python.framework/Versions/3.9/lib/python3.9/http/client.py", line 1253, in request
    self._send_request(method, url, body, headers, encode_chunked)
  File "/Library/Frameworks/Python.framework/Versions/3.9/lib/python3.9/http/client.py", line 1299, in _send_request
    self.endheaders(body, encode_chunked=encode_chunked)
  File "/Library/Frameworks/Python.framework/Versions/3.9/lib/python3.9/http/client.py", line 1248, in endheaders
    self._send_output(message_body, encode_chunked=encode_chunked)
  File "/Library/Frameworks/Python.framework/Versions/3.9/lib/python3.9/http/client.py", line 1008, in _send_output
    self.send(msg)
  File "/Library/Frameworks/Python.framework/Versions/3.9/lib/python3.9/http/client.py", line 948, in send
    self.connect()
  File "/Users/yuanyuanhe/PycharmProjects/zspaimai_ui/venv/lib/python3.9/site-packages/urllib3/connection.py", line 200, in connect
    conn = self._new_conn()
  File "/Users/yuanyuanhe/PycharmProjects/zspaimai_ui/venv/lib/python3.9/site-packages/urllib3/connection.py", line 181, in _new_conn
    raise NewConnectionError(
urllib3.exceptions.NewConnectionError: <urllib3.connection.HTTPConnection object at 0x10b1d0b80>: Failed to establish a new connection: [Errno 61] Connection refused

During handling of the above exception, another exception occurred:

Traceback (most recent call last):
  File "/Users/yuanyuanhe/PycharmProjects/zspaimai_ui/test/init.py", line 44, in setUp
    self.driver.get(url)
  File "/Users/yuanyuanhe/PycharmProjects/zspaimai_ui/venv/lib/python3.9/site-packages/selenium/webdriver/remote/webdriver.py", line 333, in get
    self.execute(Command.GET, {'url': url})
  File "/Users/yuanyuanhe/PycharmProjects/zspaimai_ui/venv/lib/python3.9/site-packages/selenium/webdriver/remote/webdriver.py", line 319, in execute
    response = self.command_executor.execute(driver_command, params)
  File "/Users/yuanyuanhe/PycharmProjects/zspaimai_ui/venv/lib/python3.9/site-packages/selenium/webdriver/remote/remote_connection.py", line 374, in execute
    return self._request(command_info[0], url, body=data)
  File "/Users/yuanyuanhe/PycharmProjects/zspaimai_ui/venv/lib/python3.9/site-packages/selenium/webdriver/remote/remote_connection.py", line 397, in _request
    resp = self._conn.request(method, url, body=body, headers=headers)
  File "/Users/yuanyuanhe/PycharmProjects/zspaimai_ui/venv/lib/python3.9/site-packages/urllib3/request.py", line 78, in request
    return self.request_encode_body(
  File "/Users/yuanyuanhe/PycharmProjects/zspaimai_ui/venv/lib/python3.9/site-packages/urllib3/request.py", line 170, in request_encode_body
    return self.urlopen(method, url, **extra_kw)
  File "/Users/yuanyuanhe/PycharmProjects/zspaimai_ui/venv/lib/python3.9/site-packages/urllib3/poolmanager.py", line 375, in urlopen
    response = conn.urlopen(method, u.request_uri, **kw)
  File "/Users/yuanyuanhe/PycharmProjects/zspaimai_ui/venv/lib/python3.9/site-packages/urllib3/connectionpool.py", line 783, in urlopen
    return self.urlopen(
  File "/Users/yuanyuanhe/PycharmProjects/zspaimai_ui/venv/lib/python3.9/site-packages/urllib3/connectionpool.py", line 783, in urlopen
    return self.urlopen(
  File "/Users/yuanyuanhe/PycharmProjects/zspaimai_ui/venv/lib/python3.9/site-packages/urllib3/connectionpool.py", line 783, in urlopen
    return self.urlopen(
  File "/Users/yuanyuanhe/PycharmProjects/zspaimai_ui/venv/lib/python3.9/site-packages/urllib3/connectionpool.py", line 755, in urlopen
    retries = retries.increment(
  File "/Users/yuanyuanhe/PycharmProjects/zspaimai_ui/venv/lib/python3.9/site-packages/urllib3/util/retry.py", line 574, in increment
    raise MaxRetryError(_pool, url, error or ResponseError(cause))
urllib3.exceptions.MaxRetryError: HTTPConnectionPool(host='127.0.0.1', port=63005): Max retries exceeded with url: /session/af66b1ad69a271d151e2b397b69d8951/url (Caused by NewConnectionError('<urllib3.connection.HTTPConnection object at 0x10b1d0b80>: Failed to establish a new connection: [Errno 61] Connection refused'))

2021-06-18 16:42:18,996 12949573632     INFO result.py(90) - 测试结束： test_click_serviceA (test.test_firstp.TestFirstp005)
2021-06-18 16:42:18,996 12949573632     INFO result.py(91) - 耗时： 3.0162129402160645
2021-06-18 16:42:18,997 8606440960     INFO test_runner.py(193) - 
Pass	test_click_biddingInfo (test.test_firstp.TestFirstp005)	验证点击页面底部 竞买须知 ，页面正确跳转
Pass	test_click_collectionGuarantee (test.test_firstp.TestFirstp005)	验证点击页面底部 藏品保障 ，页面正确跳转
Pass	test_click_contactUs (test.test_firstp.TestFirstp005)	验证点击页面底部 联系我们 ，页面正确跳转

2021-06-18 16:42:18,997 8606440960    ERROR test_runner.py(195) - 
Fail	test_click_aboutUs (test.test_firstp.TestFirstp005)	验证点击页面底部 关于我们 ，页面正确跳转
Error	test_click_guide (test.test_firstp.TestFirstp005)	验证点击页面底部 新手指南 ，页面正确跳转
Error	test_click_serviceA (test.test_firstp.TestFirstp005)	验证点击页面底部 服务协议 ，页面正确跳转

2021-06-18 16:42:18,999 8606440960     INFO test_runner.py(213) - 
测试结束！
运行时间: 0:01:15.957064
共计执行用例数量：6
执行成功用例数量：3
执行失败用例数量：1
跳过执行用例数量：0
产生异常用例数量：2

