2021-06-18 15:59:48,909 8594578944     INFO test_runner.py(156) - 预计并发线程数：1
2021-06-18 16:00:01,526 12926570496     INFO result.py(69) - 开始测试： test_click_aboutUs (test.test_firstp.TestFirstp005)
2021-06-18 16:00:02,664 12926570496     INFO result.py(156) - 测试执行通过： test_click_aboutUs (test.test_firstp.TestFirstp005)
2021-06-18 16:00:02,665 12926570496     INFO result.py(90) - 测试结束： test_click_aboutUs (test.test_firstp.TestFirstp005)
2021-06-18 16:00:02,671 12926570496     INFO result.py(91) - 耗时： 1.1385290622711182
2021-06-18 16:00:02,677 12926570496     INFO result.py(69) - 开始测试： test_click_biddingInfo (test.test_firstp.TestFirstp005)
2021-06-18 16:00:03,236 12926570496     INFO result.py(156) - 测试执行通过： test_click_biddingInfo (test.test_firstp.TestFirstp005)
2021-06-18 16:00:03,236 12926570496     INFO result.py(90) - 测试结束： test_click_biddingInfo (test.test_firstp.TestFirstp005)
2021-06-18 16:00:03,243 12926570496     INFO result.py(91) - 耗时： 0.5587620735168457
2021-06-18 16:00:03,243 12926570496     INFO result.py(69) - 开始测试： test_click_collectionGuarantee (test.test_firstp.TestFirstp005)
2021-06-18 16:00:03,852 12926570496     INFO result.py(156) - 测试执行通过： test_click_collectionGuarantee (test.test_firstp.TestFirstp005)
2021-06-18 16:00:03,858 12926570496     INFO result.py(90) - 测试结束： test_click_collectionGuarantee (test.test_firstp.TestFirstp005)
2021-06-18 16:00:03,858 12926570496     INFO result.py(91) - 耗时： 0.6153709888458252
2021-06-18 16:00:03,865 12926570496     INFO result.py(69) - 开始测试： test_click_contactUs (test.test_firstp.TestFirstp005)
2021-06-18 16:00:04,404 12926570496     INFO result.py(156) - 测试执行通过： test_click_contactUs (test.test_firstp.TestFirstp005)
2021-06-18 16:00:04,404 12926570496     INFO result.py(90) - 测试结束： test_click_contactUs (test.test_firstp.TestFirstp005)
2021-06-18 16:00:04,404 12926570496     INFO result.py(91) - 耗时： 0.539604902267456
2021-06-18 16:00:04,405 12926570496     INFO result.py(69) - 开始测试： test_click_guide (test.test_firstp.TestFirstp005)
2021-06-18 16:00:05,295 12926570496  WARNING result.py(190) - 测试未通过： test_click_guide (test.test_firstp.TestFirstp005)
Traceback (most recent call last):
  File "/Users/yuanyuanhe/PycharmProjects/zspaimai_ui/test/test_firstp.py", line 162, in test_click_guide
    self.assertEqual('中晟在线-帮助', self.driver.title)
AssertionError: '中晟在线-帮助' != '中晟在线-联系我们'
- 中晟在线-帮助
+ 中晟在线-联系我们


2021-06-18 16:00:05,296 12926570496     INFO result.py(90) - 测试结束： test_click_guide (test.test_firstp.TestFirstp005)
2021-06-18 16:00:05,296 12926570496     INFO result.py(91) - 耗时： 0.8908629417419434
2021-06-18 16:00:05,301 12926570496     INFO result.py(69) - 开始测试： test_click_ipL (test.test_firstp.TestFirstp005)
2021-06-18 16:00:05,333 12926570496     INFO result.py(142) - 跳过测试： test_click_ipL (test.test_firstp.TestFirstp005)
页面无法返回
2021-06-18 16:00:05,333 12926570496     INFO result.py(90) - 测试结束： test_click_ipL (test.test_firstp.TestFirstp005)
2021-06-18 16:00:05,334 12926570496     INFO result.py(91) - 耗时： 0.000759124755859375
2021-06-18 16:00:05,371 12926570496     INFO result.py(69) - 开始测试： test_click_serviceA (test.test_firstp.TestFirstp005)
2021-06-18 16:00:05,372 12926570496  WARNING connectionpool.py(780) - Retrying (Retry(total=2, connect=None, read=None, redirect=None, status=None)) after connection broken by 'NewConnectionError('<urllib3.connection.HTTPConnection object at 0x10a52bd90>: Failed to establish a new connection: [Errno 61] Connection refused')': /session/a26e9dfb40f3e0954c2fdb93f10ce21d/element
2021-06-18 16:00:05,372 12926570496  WARNING connectionpool.py(780) - Retrying (Retry(total=1, connect=None, read=None, redirect=None, status=None)) after connection broken by 'NewConnectionError('<urllib3.connection.HTTPConnection object at 0x10a678e80>: Failed to establish a new connection: [Errno 61] Connection refused')': /session/a26e9dfb40f3e0954c2fdb93f10ce21d/element
2021-06-18 16:00:05,373 12926570496  WARNING connectionpool.py(780) - Retrying (Retry(total=0, connect=None, read=None, redirect=None, status=None)) after connection broken by 'NewConnectionError('<urllib3.connection.HTTPConnection object at 0x10a678f10>: Failed to establish a new connection: [Errno 61] Connection refused')': /session/a26e9dfb40f3e0954c2fdb93f10ce21d/element
2021-06-18 16:00:05,577 12926570496  WARNING connectionpool.py(780) - Retrying (Retry(total=2, connect=None, read=None, redirect=None, status=None)) after connection broken by 'NewConnectionError('<urllib3.connection.HTTPConnection object at 0x10a7312e0>: Failed to establish a new connection: [Errno 61] Connection refused')': /session/a26e9dfb40f3e0954c2fdb93f10ce21d/back
2021-06-18 16:00:05,578 12926570496  WARNING connectionpool.py(780) - Retrying (Retry(total=1, connect=None, read=None, redirect=None, status=None)) after connection broken by 'NewConnectionError('<urllib3.connection.HTTPConnection object at 0x10a7314c0>: Failed to establish a new connection: [Errno 61] Connection refused')': /session/a26e9dfb40f3e0954c2fdb93f10ce21d/back
2021-06-18 16:00:05,578 12926570496  WARNING connectionpool.py(780) - Retrying (Retry(total=0, connect=None, read=None, redirect=None, status=None)) after connection broken by 'NewConnectionError('<urllib3.connection.HTTPConnection object at 0x10a7316a0>: Failed to establish a new connection: [Errno 61] Connection refused')': /session/a26e9dfb40f3e0954c2fdb93f10ce21d/back
2021-06-18 16:00:05,585 12926570496    ERROR result.py(175) - 测试产生错误： test_click_serviceA (test.test_firstp.TestFirstp005)
Traceback (most recent call last):
  File "/Users/yuanyuanhe/PycharmProjects/zspaimai_ui/venv/lib/python3.9/site-packages/urllib3/connection.py", line 169, in _new_conn
    conn = connection.create_connection(
  File "/Users/yuanyuanhe/PycharmProjects/zspaimai_ui/venv/lib/python3.9/site-packages/urllib3/util/connection.py", line 96, in create_connection
    raise err
  File "/Users/yuanyuanhe/PycharmProjects/zspaimai_ui/venv/lib/python3.9/site-packages/urllib3/util/connection.py", line 86, in create_connection
    sock.connect(sa)
ConnectionRefusedError: [Errno 61] Connection refused

During handling of the above exception, another exception occurred:

Traceback (most recent call last):
  File "/Users/yuanyuanhe/PycharmProjects/zspaimai_ui/venv/lib/python3.9/site-packages/urllib3/connectionpool.py", line 699, in urlopen
    httplib_response = self._make_request(
  File "/Users/yuanyuanhe/PycharmProjects/zspaimai_ui/venv/lib/python3.9/site-packages/urllib3/connectionpool.py", line 394, in _make_request
    conn.request(method, url, **httplib_request_kw)
  File "/Users/yuanyuanhe/PycharmProjects/zspaimai_ui/venv/lib/python3.9/site-packages/urllib3/connection.py", line 234, in request
    super(HTTPConnection, self).request(method, url, body=body, headers=headers)
  File "/Library/Frameworks/Python.framework/Versions/3.9/lib/python3.9/http/client.py", line 1253, in request
    self._send_request(method, url, body, headers, encode_chunked)
  File "/Library/Frameworks/Python.framework/Versions/3.9/lib/python3.9/http/client.py", line 1299, in _send_request
    self.endheaders(body, encode_chunked=encode_chunked)
  File "/Library/Frameworks/Python.framework/Versions/3.9/lib/python3.9/http/client.py", line 1248, in endheaders
    self._send_output(message_body, encode_chunked=encode_chunked)
  File "/Library/Frameworks/Python.framework/Versions/3.9/lib/python3.9/http/client.py", line 1008, in _send_output
    self.send(msg)
  File "/Library/Frameworks/Python.framework/Versions/3.9/lib/python3.9/http/client.py", line 948, in send
    self.connect()
  File "/Users/yuanyuanhe/PycharmProjects/zspaimai_ui/venv/lib/python3.9/site-packages/urllib3/connection.py", line 200, in connect
    conn = self._new_conn()
  File "/Users/yuanyuanhe/PycharmProjects/zspaimai_ui/venv/lib/python3.9/site-packages/urllib3/connection.py", line 181, in _new_conn
    raise NewConnectionError(
urllib3.exceptions.NewConnectionError: <urllib3.connection.HTTPConnection object at 0x10a7310d0>: Failed to establish a new connection: [Errno 61] Connection refused

During handling of the above exception, another exception occurred:

Traceback (most recent call last):
  File "/Users/yuanyuanhe/PycharmProjects/zspaimai_ui/test/test_firstp.py", line 174, in test_click_serviceA
    self.click_serviceA()
  File "/Users/yuanyuanhe/PycharmProjects/zspaimai_ui/page/firstp.py", line 124, in click_serviceA
    self.driver.find_element(*self.serviceA).click()
  File "/Users/yuanyuanhe/PycharmProjects/zspaimai_ui/venv/lib/python3.9/site-packages/selenium/webdriver/remote/webdriver.py", line 976, in find_element
    return self.execute(Command.FIND_ELEMENT, {
  File "/Users/yuanyuanhe/PycharmProjects/zspaimai_ui/venv/lib/python3.9/site-packages/selenium/webdriver/remote/webdriver.py", line 319, in execute
    response = self.command_executor.execute(driver_command, params)
  File "/Users/yuanyuanhe/PycharmProjects/zspaimai_ui/venv/lib/python3.9/site-packages/selenium/webdriver/remote/remote_connection.py", line 374, in execute
    return self._request(command_info[0], url, body=data)
  File "/Users/yuanyuanhe/PycharmProjects/zspaimai_ui/venv/lib/python3.9/site-packages/selenium/webdriver/remote/remote_connection.py", line 397, in _request
    resp = self._conn.request(method, url, body=body, headers=headers)
  File "/Users/yuanyuanhe/PycharmProjects/zspaimai_ui/venv/lib/python3.9/site-packages/urllib3/request.py", line 78, in request
    return self.request_encode_body(
  File "/Users/yuanyuanhe/PycharmProjects/zspaimai_ui/venv/lib/python3.9/site-packages/urllib3/request.py", line 170, in request_encode_body
    return self.urlopen(method, url, **extra_kw)
  File "/Users/yuanyuanhe/PycharmProjects/zspaimai_ui/venv/lib/python3.9/site-packages/urllib3/poolmanager.py", line 375, in urlopen
    response = conn.urlopen(method, u.request_uri, **kw)
  File "/Users/yuanyuanhe/PycharmProjects/zspaimai_ui/venv/lib/python3.9/site-packages/urllib3/connectionpool.py", line 783, in urlopen
    return self.urlopen(
  File "/Users/yuanyuanhe/PycharmProjects/zspaimai_ui/venv/lib/python3.9/site-packages/urllib3/connectionpool.py", line 783, in urlopen
    return self.urlopen(
  File "/Users/yuanyuanhe/PycharmProjects/zspaimai_ui/venv/lib/python3.9/site-packages/urllib3/connectionpool.py", line 783, in urlopen
    return self.urlopen(
  File "/Users/yuanyuanhe/PycharmProjects/zspaimai_ui/venv/lib/python3.9/site-packages/urllib3/connectionpool.py", line 755, in urlopen
    retries = retries.increment(
  File "/Users/yuanyuanhe/PycharmProjects/zspaimai_ui/venv/lib/python3.9/site-packages/urllib3/util/retry.py", line 574, in increment
    raise MaxRetryError(_pool, url, error or ResponseError(cause))
urllib3.exceptions.MaxRetryError: HTTPConnectionPool(host='127.0.0.1', port=61226): Max retries exceeded with url: /session/a26e9dfb40f3e0954c2fdb93f10ce21d/element (Caused by NewConnectionError('<urllib3.connection.HTTPConnection object at 0x10a7310d0>: Failed to establish a new connection: [Errno 61] Connection refused'))

2021-06-18 16:00:05,585 12926570496    ERROR result.py(175) - 测试产生错误： test_click_serviceA (test.test_firstp.TestFirstp005)
Traceback (most recent call last):
  File "/Users/yuanyuanhe/PycharmProjects/zspaimai_ui/venv/lib/python3.9/site-packages/urllib3/connection.py", line 169, in _new_conn
    conn = connection.create_connection(
  File "/Users/yuanyuanhe/PycharmProjects/zspaimai_ui/venv/lib/python3.9/site-packages/urllib3/util/connection.py", line 96, in create_connection
    raise err
  File "/Users/yuanyuanhe/PycharmProjects/zspaimai_ui/venv/lib/python3.9/site-packages/urllib3/util/connection.py", line 86, in create_connection
    sock.connect(sa)
ConnectionRefusedError: [Errno 61] Connection refused

During handling of the above exception, another exception occurred:

Traceback (most recent call last):
  File "/Users/yuanyuanhe/PycharmProjects/zspaimai_ui/venv/lib/python3.9/site-packages/urllib3/connectionpool.py", line 699, in urlopen
    httplib_response = self._make_request(
  File "/Users/yuanyuanhe/PycharmProjects/zspaimai_ui/venv/lib/python3.9/site-packages/urllib3/connectionpool.py", line 394, in _make_request
    conn.request(method, url, **httplib_request_kw)
  File "/Users/yuanyuanhe/PycharmProjects/zspaimai_ui/venv/lib/python3.9/site-packages/urllib3/connection.py", line 234, in request
    super(HTTPConnection, self).request(method, url, body=body, headers=headers)
  File "/Library/Frameworks/Python.framework/Versions/3.9/lib/python3.9/http/client.py", line 1253, in request
    self._send_request(method, url, body, headers, encode_chunked)
  File "/Library/Frameworks/Python.framework/Versions/3.9/lib/python3.9/http/client.py", line 1299, in _send_request
    self.endheaders(body, encode_chunked=encode_chunked)
  File "/Library/Frameworks/Python.framework/Versions/3.9/lib/python3.9/http/client.py", line 1248, in endheaders
    self._send_output(message_body, encode_chunked=encode_chunked)
  File "/Library/Frameworks/Python.framework/Versions/3.9/lib/python3.9/http/client.py", line 1008, in _send_output
    self.send(msg)
  File "/Library/Frameworks/Python.framework/Versions/3.9/lib/python3.9/http/client.py", line 948, in send
    self.connect()
  File "/Users/yuanyuanhe/PycharmProjects/zspaimai_ui/venv/lib/python3.9/site-packages/urllib3/connection.py", line 200, in connect
    conn = self._new_conn()
  File "/Users/yuanyuanhe/PycharmProjects/zspaimai_ui/venv/lib/python3.9/site-packages/urllib3/connection.py", line 181, in _new_conn
    raise NewConnectionError(
urllib3.exceptions.NewConnectionError: <urllib3.connection.HTTPConnection object at 0x10a731850>: Failed to establish a new connection: [Errno 61] Connection refused

During handling of the above exception, another exception occurred:

Traceback (most recent call last):
  File "/Users/yuanyuanhe/PycharmProjects/zspaimai_ui/test/init.py", line 41, in tearDown
    self.driver.back()
  File "/Users/yuanyuanhe/PycharmProjects/zspaimai_ui/venv/lib/python3.9/site-packages/selenium/webdriver/remote/webdriver.py", line 813, in back
    self.execute(Command.GO_BACK)
  File "/Users/yuanyuanhe/PycharmProjects/zspaimai_ui/venv/lib/python3.9/site-packages/selenium/webdriver/remote/webdriver.py", line 319, in execute
    response = self.command_executor.execute(driver_command, params)
  File "/Users/yuanyuanhe/PycharmProjects/zspaimai_ui/venv/lib/python3.9/site-packages/selenium/webdriver/remote/remote_connection.py", line 374, in execute
    return self._request(command_info[0], url, body=data)
  File "/Users/yuanyuanhe/PycharmProjects/zspaimai_ui/venv/lib/python3.9/site-packages/selenium/webdriver/remote/remote_connection.py", line 397, in _request
    resp = self._conn.request(method, url, body=body, headers=headers)
  File "/Users/yuanyuanhe/PycharmProjects/zspaimai_ui/venv/lib/python3.9/site-packages/urllib3/request.py", line 78, in request
    return self.request_encode_body(
  File "/Users/yuanyuanhe/PycharmProjects/zspaimai_ui/venv/lib/python3.9/site-packages/urllib3/request.py", line 170, in request_encode_body
    return self.urlopen(method, url, **extra_kw)
  File "/Users/yuanyuanhe/PycharmProjects/zspaimai_ui/venv/lib/python3.9/site-packages/urllib3/poolmanager.py", line 375, in urlopen
    response = conn.urlopen(method, u.request_uri, **kw)
  File "/Users/yuanyuanhe/PycharmProjects/zspaimai_ui/venv/lib/python3.9/site-packages/urllib3/connectionpool.py", line 783, in urlopen
    return self.urlopen(
  File "/Users/yuanyuanhe/PycharmProjects/zspaimai_ui/venv/lib/python3.9/site-packages/urllib3/connectionpool.py", line 783, in urlopen
    return self.urlopen(
  File "/Users/yuanyuanhe/PycharmProjects/zspaimai_ui/venv/lib/python3.9/site-packages/urllib3/connectionpool.py", line 783, in urlopen
    return self.urlopen(
  File "/Users/yuanyuanhe/PycharmProjects/zspaimai_ui/venv/lib/python3.9/site-packages/urllib3/connectionpool.py", line 755, in urlopen
    retries = retries.increment(
  File "/Users/yuanyuanhe/PycharmProjects/zspaimai_ui/venv/lib/python3.9/site-packages/urllib3/util/retry.py", line 574, in increment
    raise MaxRetryError(_pool, url, error or ResponseError(cause))
urllib3.exceptions.MaxRetryError: HTTPConnectionPool(host='127.0.0.1', port=61226): Max retries exceeded with url: /session/a26e9dfb40f3e0954c2fdb93f10ce21d/back (Caused by NewConnectionError('<urllib3.connection.HTTPConnection object at 0x10a731850>: Failed to establish a new connection: [Errno 61] Connection refused'))

2021-06-18 16:00:05,586 12926570496     INFO result.py(90) - 测试结束： test_click_serviceA (test.test_firstp.TestFirstp005)
2021-06-18 16:00:05,586 12926570496     INFO result.py(91) - 耗时： 0.21455001831054688
2021-06-18 16:00:05,586 8594578944     INFO test_runner.py(193) - 
Pass	test_click_aboutUs (test.test_firstp.TestFirstp005)	验证点击页面底部 关于我们 ，页面正确跳转
Pass	test_click_biddingInfo (test.test_firstp.TestFirstp005)	验证点击页面底部 竞买须知 ，页面正确跳转
Pass	test_click_collectionGuarantee (test.test_firstp.TestFirstp005)	验证点击页面底部 藏品保障 ，页面正确跳转
Pass	test_click_contactUs (test.test_firstp.TestFirstp005)	验证点击页面底部 联系我们 ，页面正确跳转

2021-06-18 16:00:05,586 8594578944    ERROR test_runner.py(195) - 
Fail	test_click_guide (test.test_firstp.TestFirstp005)	验证点击页面底部 新手指南 ，页面正确跳转
Skip	test_click_ipL (test.test_firstp.TestFirstp005)	验证点击页面底部的 粤ICP备2021041206号 链接，正确打开页面
Error	test_click_serviceA (test.test_firstp.TestFirstp005)	验证点击页面底部 服务协议 ，页面正确跳转
Error	test_click_serviceA (test.test_firstp.TestFirstp005)	验证点击页面底部 服务协议 ，页面正确跳转

2021-06-18 16:00:05,587 8594578944     INFO test_runner.py(213) - 
测试结束！
运行时间: 0:00:16.861259
共计执行用例数量：7
执行成功用例数量：4
执行失败用例数量：1
跳过执行用例数量：1
产生异常用例数量：1

