2021-06-18 16:21:31,569 8663518720     INFO test_runner.py(156) - 预计并发线程数：1
2021-06-18 16:21:50,369 13062651904     INFO result.py(69) - 开始测试： test_click_aboutUs (test.test_firstp.TestFirstp005)
2021-06-18 16:21:54,248 13062651904     INFO result.py(156) - 测试执行通过： test_click_aboutUs (test.test_firstp.TestFirstp005)
2021-06-18 16:21:54,248 13062651904     INFO result.py(90) - 测试结束： test_click_aboutUs (test.test_firstp.TestFirstp005)
2021-06-18 16:21:54,255 13062651904     INFO result.py(91) - 耗时： 3.8724379539489746
2021-06-18 16:21:54,261 13062651904     INFO result.py(69) - 开始测试： test_click_biddingInfo (test.test_firstp.TestFirstp005)
2021-06-18 16:21:57,550 13062651904     INFO result.py(156) - 测试执行通过： test_click_biddingInfo (test.test_firstp.TestFirstp005)
2021-06-18 16:21:57,550 13062651904     INFO result.py(90) - 测试结束： test_click_biddingInfo (test.test_firstp.TestFirstp005)
2021-06-18 16:21:57,556 13062651904     INFO result.py(91) - 耗时： 3.2885639667510986
2021-06-18 16:21:57,557 13062651904     INFO result.py(69) - 开始测试： test_click_collectionGuarantee (test.test_firstp.TestFirstp005)
2021-06-18 16:22:00,682 13062651904     INFO result.py(156) - 测试执行通过： test_click_collectionGuarantee (test.test_firstp.TestFirstp005)
2021-06-18 16:22:00,682 13062651904     INFO result.py(90) - 测试结束： test_click_collectionGuarantee (test.test_firstp.TestFirstp005)
2021-06-18 16:22:00,682 13062651904     INFO result.py(91) - 耗时： 3.1253750324249268
2021-06-18 16:22:00,682 13062651904     INFO result.py(69) - 开始测试： test_click_contactUs (test.test_firstp.TestFirstp005)
2021-06-18 16:22:00,682 13062651904     INFO result.py(142) - 跳过测试： test_click_contactUs (test.test_firstp.TestFirstp005)
运行联系我们后，页面经常报错
2021-06-18 16:22:00,683 13062651904     INFO result.py(90) - 测试结束： test_click_contactUs (test.test_firstp.TestFirstp005)
2021-06-18 16:22:00,683 13062651904     INFO result.py(91) - 耗时： 0.0001609325408935547
2021-06-18 16:22:00,683 13062651904     INFO result.py(69) - 开始测试： test_click_guide (test.test_firstp.TestFirstp005)
2021-06-18 16:22:00,760 13062651904  WARNING connectionpool.py(304) - Connection pool is full, discarding connection: 127.0.0.1
2021-06-18 16:22:03,793 13062651904  WARNING connectionpool.py(780) - Retrying (Retry(total=2, connect=None, read=None, redirect=None, status=None)) after connection broken by 'NewConnectionError('<urllib3.connection.HTTPConnection object at 0x10e54fcd0>: Failed to establish a new connection: [Errno 61] Connection refused')': /session/6f7cc85736e7318437f6098e21d362ea/back
2021-06-18 16:22:03,818 13062651904  WARNING connectionpool.py(780) - Retrying (Retry(total=1, connect=None, read=None, redirect=None, status=None)) after connection broken by 'NewConnectionError('<urllib3.connection.HTTPConnection object at 0x10e536220>: Failed to establish a new connection: [Errno 61] Connection refused')': /session/6f7cc85736e7318437f6098e21d362ea/back
2021-06-18 16:22:03,843 13062651904  WARNING connectionpool.py(780) - Retrying (Retry(total=0, connect=None, read=None, redirect=None, status=None)) after connection broken by 'NewConnectionError('<urllib3.connection.HTTPConnection object at 0x10e6ad070>: Failed to establish a new connection: [Errno 61] Connection refused')': /session/6f7cc85736e7318437f6098e21d362ea/back
2021-06-18 16:22:03,955 13062651904    ERROR result.py(175) - 测试产生错误： test_click_guide (test.test_firstp.TestFirstp005)
Traceback (most recent call last):
  File "/Users/yuanyuanhe/PycharmProjects/zspaimai_ui/test/test_firstp.py", line 161, in test_click_guide
    self.click_guildL()
  File "/Users/yuanyuanhe/PycharmProjects/zspaimai_ui/page/firstp.py", line 118, in click_guildL
    self.driver.find_element(*self.guideL).click()
  File "/Users/yuanyuanhe/PycharmProjects/zspaimai_ui/venv/lib/python3.9/site-packages/selenium/webdriver/remote/webelement.py", line 80, in click
    self._execute(Command.CLICK_ELEMENT)
  File "/Users/yuanyuanhe/PycharmProjects/zspaimai_ui/venv/lib/python3.9/site-packages/selenium/webdriver/remote/webelement.py", line 633, in _execute
    return self._parent.execute(command, params)
  File "/Users/yuanyuanhe/PycharmProjects/zspaimai_ui/venv/lib/python3.9/site-packages/selenium/webdriver/remote/webdriver.py", line 321, in execute
    self.error_handler.check_response(response)
  File "/Users/yuanyuanhe/PycharmProjects/zspaimai_ui/venv/lib/python3.9/site-packages/selenium/webdriver/remote/errorhandler.py", line 242, in check_response
    raise exception_class(message, screen, stacktrace)
selenium.common.exceptions.InvalidSessionIdException: Message: invalid session id


2021-06-18 16:22:04,167 13062651904    ERROR result.py(175) - 测试产生错误： test_click_guide (test.test_firstp.TestFirstp005)
Traceback (most recent call last):
  File "/Users/yuanyuanhe/PycharmProjects/zspaimai_ui/venv/lib/python3.9/site-packages/urllib3/connection.py", line 169, in _new_conn
    conn = connection.create_connection(
  File "/Users/yuanyuanhe/PycharmProjects/zspaimai_ui/venv/lib/python3.9/site-packages/urllib3/util/connection.py", line 96, in create_connection
    raise err
  File "/Users/yuanyuanhe/PycharmProjects/zspaimai_ui/venv/lib/python3.9/site-packages/urllib3/util/connection.py", line 86, in create_connection
    sock.connect(sa)
ConnectionRefusedError: [Errno 61] Connection refused

During handling of the above exception, another exception occurred:

Traceback (most recent call last):
  File "/Users/yuanyuanhe/PycharmProjects/zspaimai_ui/venv/lib/python3.9/site-packages/urllib3/connectionpool.py", line 699, in urlopen
    httplib_response = self._make_request(
  File "/Users/yuanyuanhe/PycharmProjects/zspaimai_ui/venv/lib/python3.9/site-packages/urllib3/connectionpool.py", line 394, in _make_request
    conn.request(method, url, **httplib_request_kw)
  File "/Users/yuanyuanhe/PycharmProjects/zspaimai_ui/venv/lib/python3.9/site-packages/urllib3/connection.py", line 234, in request
    super(HTTPConnection, self).request(method, url, body=body, headers=headers)
  File "/Library/Frameworks/Python.framework/Versions/3.9/lib/python3.9/http/client.py", line 1253, in request
    self._send_request(method, url, body, headers, encode_chunked)
  File "/Library/Frameworks/Python.framework/Versions/3.9/lib/python3.9/http/client.py", line 1299, in _send_request
    self.endheaders(body, encode_chunked=encode_chunked)
  File "/Library/Frameworks/Python.framework/Versions/3.9/lib/python3.9/http/client.py", line 1248, in endheaders
    self._send_output(message_body, encode_chunked=encode_chunked)
  File "/Library/Frameworks/Python.framework/Versions/3.9/lib/python3.9/http/client.py", line 1008, in _send_output
    self.send(msg)
  File "/Library/Frameworks/Python.framework/Versions/3.9/lib/python3.9/http/client.py", line 948, in send
    self.connect()
  File "/Users/yuanyuanhe/PycharmProjects/zspaimai_ui/venv/lib/python3.9/site-packages/urllib3/connection.py", line 200, in connect
    conn = self._new_conn()
  File "/Users/yuanyuanhe/PycharmProjects/zspaimai_ui/venv/lib/python3.9/site-packages/urllib3/connection.py", line 181, in _new_conn
    raise NewConnectionError(
urllib3.exceptions.NewConnectionError: <urllib3.connection.HTTPConnection object at 0x10e6ad280>: Failed to establish a new connection: [Errno 61] Connection refused

During handling of the above exception, another exception occurred:

Traceback (most recent call last):
  File "/Users/yuanyuanhe/PycharmProjects/zspaimai_ui/test/init.py", line 41, in tearDown
    self.driver.back()
  File "/Users/yuanyuanhe/PycharmProjects/zspaimai_ui/venv/lib/python3.9/site-packages/selenium/webdriver/remote/webdriver.py", line 813, in back
    self.execute(Command.GO_BACK)
  File "/Users/yuanyuanhe/PycharmProjects/zspaimai_ui/venv/lib/python3.9/site-packages/selenium/webdriver/remote/webdriver.py", line 319, in execute
    response = self.command_executor.execute(driver_command, params)
  File "/Users/yuanyuanhe/PycharmProjects/zspaimai_ui/venv/lib/python3.9/site-packages/selenium/webdriver/remote/remote_connection.py", line 374, in execute
    return self._request(command_info[0], url, body=data)
  File "/Users/yuanyuanhe/PycharmProjects/zspaimai_ui/venv/lib/python3.9/site-packages/selenium/webdriver/remote/remote_connection.py", line 397, in _request
    resp = self._conn.request(method, url, body=body, headers=headers)
  File "/Users/yuanyuanhe/PycharmProjects/zspaimai_ui/venv/lib/python3.9/site-packages/urllib3/request.py", line 78, in request
    return self.request_encode_body(
  File "/Users/yuanyuanhe/PycharmProjects/zspaimai_ui/venv/lib/python3.9/site-packages/urllib3/request.py", line 170, in request_encode_body
    return self.urlopen(method, url, **extra_kw)
  File "/Users/yuanyuanhe/PycharmProjects/zspaimai_ui/venv/lib/python3.9/site-packages/urllib3/poolmanager.py", line 375, in urlopen
    response = conn.urlopen(method, u.request_uri, **kw)
  File "/Users/yuanyuanhe/PycharmProjects/zspaimai_ui/venv/lib/python3.9/site-packages/urllib3/connectionpool.py", line 783, in urlopen
    return self.urlopen(
  File "/Users/yuanyuanhe/PycharmProjects/zspaimai_ui/venv/lib/python3.9/site-packages/urllib3/connectionpool.py", line 783, in urlopen
    return self.urlopen(
  File "/Users/yuanyuanhe/PycharmProjects/zspaimai_ui/venv/lib/python3.9/site-packages/urllib3/connectionpool.py", line 783, in urlopen
    return self.urlopen(
  File "/Users/yuanyuanhe/PycharmProjects/zspaimai_ui/venv/lib/python3.9/site-packages/urllib3/connectionpool.py", line 755, in urlopen
    retries = retries.increment(
  File "/Users/yuanyuanhe/PycharmProjects/zspaimai_ui/venv/lib/python3.9/site-packages/urllib3/util/retry.py", line 574, in increment
    raise MaxRetryError(_pool, url, error or ResponseError(cause))
urllib3.exceptions.MaxRetryError: HTTPConnectionPool(host='127.0.0.1', port=62005): Max retries exceeded with url: /session/6f7cc85736e7318437f6098e21d362ea/back (Caused by NewConnectionError('<urllib3.connection.HTTPConnection object at 0x10e6ad280>: Failed to establish a new connection: [Errno 61] Connection refused'))

2021-06-18 16:22:04,167 13062651904     INFO result.py(90) - 测试结束： test_click_guide (test.test_firstp.TestFirstp005)
2021-06-18 16:22:04,167 13062651904     INFO result.py(91) - 耗时： 3.48420786857605
2021-06-18 16:22:04,167 13062651904     INFO result.py(69) - 开始测试： test_click_serviceA (test.test_firstp.TestFirstp005)
2021-06-18 16:22:04,168 13062651904  WARNING connectionpool.py(780) - Retrying (Retry(total=2, connect=None, read=None, redirect=None, status=None)) after connection broken by 'NewConnectionError('<urllib3.connection.HTTPConnection object at 0x10e6ad8e0>: Failed to establish a new connection: [Errno 61] Connection refused')': /session/6f7cc85736e7318437f6098e21d362ea/element
2021-06-18 16:22:04,168 13062651904  WARNING connectionpool.py(780) - Retrying (Retry(total=1, connect=None, read=None, redirect=None, status=None)) after connection broken by 'NewConnectionError('<urllib3.connection.HTTPConnection object at 0x10e6ad9a0>: Failed to establish a new connection: [Errno 61] Connection refused')': /session/6f7cc85736e7318437f6098e21d362ea/element
2021-06-18 16:22:04,169 13062651904  WARNING connectionpool.py(780) - Retrying (Retry(total=0, connect=None, read=None, redirect=None, status=None)) after connection broken by 'NewConnectionError('<urllib3.connection.HTTPConnection object at 0x10e6adaf0>: Failed to establish a new connection: [Errno 61] Connection refused')': /session/6f7cc85736e7318437f6098e21d362ea/element
2021-06-18 16:22:07,179 13062651904  WARNING connectionpool.py(780) - Retrying (Retry(total=2, connect=None, read=None, redirect=None, status=None)) after connection broken by 'NewConnectionError('<urllib3.connection.HTTPConnection object at 0x10e6ade20>: Failed to establish a new connection: [Errno 61] Connection refused')': /session/6f7cc85736e7318437f6098e21d362ea/back
2021-06-18 16:22:07,180 13062651904  WARNING connectionpool.py(780) - Retrying (Retry(total=1, connect=None, read=None, redirect=None, status=None)) after connection broken by 'NewConnectionError('<urllib3.connection.HTTPConnection object at 0x10e54f760>: Failed to establish a new connection: [Errno 61] Connection refused')': /session/6f7cc85736e7318437f6098e21d362ea/back
2021-06-18 16:22:07,182 13062651904  WARNING connectionpool.py(780) - Retrying (Retry(total=0, connect=None, read=None, redirect=None, status=None)) after connection broken by 'NewConnectionError('<urllib3.connection.HTTPConnection object at 0x10e54fc70>: Failed to establish a new connection: [Errno 61] Connection refused')': /session/6f7cc85736e7318437f6098e21d362ea/back
2021-06-18 16:22:07,185 13062651904    ERROR result.py(175) - 测试产生错误： test_click_serviceA (test.test_firstp.TestFirstp005)
Traceback (most recent call last):
  File "/Users/yuanyuanhe/PycharmProjects/zspaimai_ui/venv/lib/python3.9/site-packages/urllib3/connection.py", line 169, in _new_conn
    conn = connection.create_connection(
  File "/Users/yuanyuanhe/PycharmProjects/zspaimai_ui/venv/lib/python3.9/site-packages/urllib3/util/connection.py", line 96, in create_connection
    raise err
  File "/Users/yuanyuanhe/PycharmProjects/zspaimai_ui/venv/lib/python3.9/site-packages/urllib3/util/connection.py", line 86, in create_connection
    sock.connect(sa)
ConnectionRefusedError: [Errno 61] Connection refused

During handling of the above exception, another exception occurred:

Traceback (most recent call last):
  File "/Users/yuanyuanhe/PycharmProjects/zspaimai_ui/venv/lib/python3.9/site-packages/urllib3/connectionpool.py", line 699, in urlopen
    httplib_response = self._make_request(
  File "/Users/yuanyuanhe/PycharmProjects/zspaimai_ui/venv/lib/python3.9/site-packages/urllib3/connectionpool.py", line 394, in _make_request
    conn.request(method, url, **httplib_request_kw)
  File "/Users/yuanyuanhe/PycharmProjects/zspaimai_ui/venv/lib/python3.9/site-packages/urllib3/connection.py", line 234, in request
    super(HTTPConnection, self).request(method, url, body=body, headers=headers)
  File "/Library/Frameworks/Python.framework/Versions/3.9/lib/python3.9/http/client.py", line 1253, in request
    self._send_request(method, url, body, headers, encode_chunked)
  File "/Library/Frameworks/Python.framework/Versions/3.9/lib/python3.9/http/client.py", line 1299, in _send_request
    self.endheaders(body, encode_chunked=encode_chunked)
  File "/Library/Frameworks/Python.framework/Versions/3.9/lib/python3.9/http/client.py", line 1248, in endheaders
    self._send_output(message_body, encode_chunked=encode_chunked)
  File "/Library/Frameworks/Python.framework/Versions/3.9/lib/python3.9/http/client.py", line 1008, in _send_output
    self.send(msg)
  File "/Library/Frameworks/Python.framework/Versions/3.9/lib/python3.9/http/client.py", line 948, in send
    self.connect()
  File "/Users/yuanyuanhe/PycharmProjects/zspaimai_ui/venv/lib/python3.9/site-packages/urllib3/connection.py", line 200, in connect
    conn = self._new_conn()
  File "/Users/yuanyuanhe/PycharmProjects/zspaimai_ui/venv/lib/python3.9/site-packages/urllib3/connection.py", line 181, in _new_conn
    raise NewConnectionError(
urllib3.exceptions.NewConnectionError: <urllib3.connection.HTTPConnection object at 0x10e6adc40>: Failed to establish a new connection: [Errno 61] Connection refused

During handling of the above exception, another exception occurred:

Traceback (most recent call last):
  File "/Users/yuanyuanhe/PycharmProjects/zspaimai_ui/test/test_firstp.py", line 175, in test_click_serviceA
    self.click_serviceA()
  File "/Users/yuanyuanhe/PycharmProjects/zspaimai_ui/page/firstp.py", line 124, in click_serviceA
    self.driver.find_element(*self.serviceA).click()
  File "/Users/yuanyuanhe/PycharmProjects/zspaimai_ui/venv/lib/python3.9/site-packages/selenium/webdriver/remote/webdriver.py", line 976, in find_element
    return self.execute(Command.FIND_ELEMENT, {
  File "/Users/yuanyuanhe/PycharmProjects/zspaimai_ui/venv/lib/python3.9/site-packages/selenium/webdriver/remote/webdriver.py", line 319, in execute
    response = self.command_executor.execute(driver_command, params)
  File "/Users/yuanyuanhe/PycharmProjects/zspaimai_ui/venv/lib/python3.9/site-packages/selenium/webdriver/remote/remote_connection.py", line 374, in execute
    return self._request(command_info[0], url, body=data)
  File "/Users/yuanyuanhe/PycharmProjects/zspaimai_ui/venv/lib/python3.9/site-packages/selenium/webdriver/remote/remote_connection.py", line 397, in _request
    resp = self._conn.request(method, url, body=body, headers=headers)
  File "/Users/yuanyuanhe/PycharmProjects/zspaimai_ui/venv/lib/python3.9/site-packages/urllib3/request.py", line 78, in request
    return self.request_encode_body(
  File "/Users/yuanyuanhe/PycharmProjects/zspaimai_ui/venv/lib/python3.9/site-packages/urllib3/request.py", line 170, in request_encode_body
    return self.urlopen(method, url, **extra_kw)
  File "/Users/yuanyuanhe/PycharmProjects/zspaimai_ui/venv/lib/python3.9/site-packages/urllib3/poolmanager.py", line 375, in urlopen
    response = conn.urlopen(method, u.request_uri, **kw)
  File "/Users/yuanyuanhe/PycharmProjects/zspaimai_ui/venv/lib/python3.9/site-packages/urllib3/connectionpool.py", line 783, in urlopen
    return self.urlopen(
  File "/Users/yuanyuanhe/PycharmProjects/zspaimai_ui/venv/lib/python3.9/site-packages/urllib3/connectionpool.py", line 783, in urlopen
    return self.urlopen(
  File "/Users/yuanyuanhe/PycharmProjects/zspaimai_ui/venv/lib/python3.9/site-packages/urllib3/connectionpool.py", line 783, in urlopen
    return self.urlopen(
  File "/Users/yuanyuanhe/PycharmProjects/zspaimai_ui/venv/lib/python3.9/site-packages/urllib3/connectionpool.py", line 755, in urlopen
    retries = retries.increment(
  File "/Users/yuanyuanhe/PycharmProjects/zspaimai_ui/venv/lib/python3.9/site-packages/urllib3/util/retry.py", line 574, in increment
    raise MaxRetryError(_pool, url, error or ResponseError(cause))
urllib3.exceptions.MaxRetryError: HTTPConnectionPool(host='127.0.0.1', port=62005): Max retries exceeded with url: /session/6f7cc85736e7318437f6098e21d362ea/element (Caused by NewConnectionError('<urllib3.connection.HTTPConnection object at 0x10e6adc40>: Failed to establish a new connection: [Errno 61] Connection refused'))

2021-06-18 16:22:07,185 13062651904    ERROR result.py(175) - 测试产生错误： test_click_serviceA (test.test_firstp.TestFirstp005)
Traceback (most recent call last):
  File "/Users/yuanyuanhe/PycharmProjects/zspaimai_ui/venv/lib/python3.9/site-packages/urllib3/connection.py", line 169, in _new_conn
    conn = connection.create_connection(
  File "/Users/yuanyuanhe/PycharmProjects/zspaimai_ui/venv/lib/python3.9/site-packages/urllib3/util/connection.py", line 96, in create_connection
    raise err
  File "/Users/yuanyuanhe/PycharmProjects/zspaimai_ui/venv/lib/python3.9/site-packages/urllib3/util/connection.py", line 86, in create_connection
    sock.connect(sa)
ConnectionRefusedError: [Errno 61] Connection refused

During handling of the above exception, another exception occurred:

Traceback (most recent call last):
  File "/Users/yuanyuanhe/PycharmProjects/zspaimai_ui/venv/lib/python3.9/site-packages/urllib3/connectionpool.py", line 699, in urlopen
    httplib_response = self._make_request(
  File "/Users/yuanyuanhe/PycharmProjects/zspaimai_ui/venv/lib/python3.9/site-packages/urllib3/connectionpool.py", line 394, in _make_request
    conn.request(method, url, **httplib_request_kw)
  File "/Users/yuanyuanhe/PycharmProjects/zspaimai_ui/venv/lib/python3.9/site-packages/urllib3/connection.py", line 234, in request
    super(HTTPConnection, self).request(method, url, body=body, headers=headers)
  File "/Library/Frameworks/Python.framework/Versions/3.9/lib/python3.9/http/client.py", line 1253, in request
    self._send_request(method, url, body, headers, encode_chunked)
  File "/Library/Frameworks/Python.framework/Versions/3.9/lib/python3.9/http/client.py", line 1299, in _send_request
    self.endheaders(body, encode_chunked=encode_chunked)
  File "/Library/Frameworks/Python.framework/Versions/3.9/lib/python3.9/http/client.py", line 1248, in endheaders
    self._send_output(message_body, encode_chunked=encode_chunked)
  File "/Library/Frameworks/Python.framework/Versions/3.9/lib/python3.9/http/client.py", line 1008, in _send_output
    self.send(msg)
  File "/Library/Frameworks/Python.framework/Versions/3.9/lib/python3.9/http/client.py", line 948, in send
    self.connect()
  File "/Users/yuanyuanhe/PycharmProjects/zspaimai_ui/venv/lib/python3.9/site-packages/urllib3/connection.py", line 200, in connect
    conn = self._new_conn()
  File "/Users/yuanyuanhe/PycharmProjects/zspaimai_ui/venv/lib/python3.9/site-packages/urllib3/connection.py", line 181, in _new_conn
    raise NewConnectionError(
urllib3.exceptions.NewConnectionError: <urllib3.connection.HTTPConnection object at 0x10e6ad310>: Failed to establish a new connection: [Errno 61] Connection refused

During handling of the above exception, another exception occurred:

Traceback (most recent call last):
  File "/Users/yuanyuanhe/PycharmProjects/zspaimai_ui/test/init.py", line 41, in tearDown
    self.driver.back()
  File "/Users/yuanyuanhe/PycharmProjects/zspaimai_ui/venv/lib/python3.9/site-packages/selenium/webdriver/remote/webdriver.py", line 813, in back
    self.execute(Command.GO_BACK)
  File "/Users/yuanyuanhe/PycharmProjects/zspaimai_ui/venv/lib/python3.9/site-packages/selenium/webdriver/remote/webdriver.py", line 319, in execute
    response = self.command_executor.execute(driver_command, params)
  File "/Users/yuanyuanhe/PycharmProjects/zspaimai_ui/venv/lib/python3.9/site-packages/selenium/webdriver/remote/remote_connection.py", line 374, in execute
    return self._request(command_info[0], url, body=data)
  File "/Users/yuanyuanhe/PycharmProjects/zspaimai_ui/venv/lib/python3.9/site-packages/selenium/webdriver/remote/remote_connection.py", line 397, in _request
    resp = self._conn.request(method, url, body=body, headers=headers)
  File "/Users/yuanyuanhe/PycharmProjects/zspaimai_ui/venv/lib/python3.9/site-packages/urllib3/request.py", line 78, in request
    return self.request_encode_body(
  File "/Users/yuanyuanhe/PycharmProjects/zspaimai_ui/venv/lib/python3.9/site-packages/urllib3/request.py", line 170, in request_encode_body
    return self.urlopen(method, url, **extra_kw)
  File "/Users/yuanyuanhe/PycharmProjects/zspaimai_ui/venv/lib/python3.9/site-packages/urllib3/poolmanager.py", line 375, in urlopen
    response = conn.urlopen(method, u.request_uri, **kw)
  File "/Users/yuanyuanhe/PycharmProjects/zspaimai_ui/venv/lib/python3.9/site-packages/urllib3/connectionpool.py", line 783, in urlopen
    return self.urlopen(
  File "/Users/yuanyuanhe/PycharmProjects/zspaimai_ui/venv/lib/python3.9/site-packages/urllib3/connectionpool.py", line 783, in urlopen
    return self.urlopen(
  File "/Users/yuanyuanhe/PycharmProjects/zspaimai_ui/venv/lib/python3.9/site-packages/urllib3/connectionpool.py", line 783, in urlopen
    return self.urlopen(
  File "/Users/yuanyuanhe/PycharmProjects/zspaimai_ui/venv/lib/python3.9/site-packages/urllib3/connectionpool.py", line 755, in urlopen
    retries = retries.increment(
  File "/Users/yuanyuanhe/PycharmProjects/zspaimai_ui/venv/lib/python3.9/site-packages/urllib3/util/retry.py", line 574, in increment
    raise MaxRetryError(_pool, url, error or ResponseError(cause))
urllib3.exceptions.MaxRetryError: HTTPConnectionPool(host='127.0.0.1', port=62005): Max retries exceeded with url: /session/6f7cc85736e7318437f6098e21d362ea/back (Caused by NewConnectionError('<urllib3.connection.HTTPConnection object at 0x10e6ad310>: Failed to establish a new connection: [Errno 61] Connection refused'))

2021-06-18 16:22:07,186 13062651904     INFO result.py(90) - 测试结束： test_click_serviceA (test.test_firstp.TestFirstp005)
2021-06-18 16:22:07,186 13062651904     INFO result.py(91) - 耗时： 3.0183260440826416
2021-06-18 16:22:07,186 8663518720     INFO test_runner.py(193) - 
Pass	test_click_aboutUs (test.test_firstp.TestFirstp005)	验证点击页面底部 关于我们 ，页面正确跳转
Pass	test_click_biddingInfo (test.test_firstp.TestFirstp005)	验证点击页面底部 竞买须知 ，页面正确跳转
Pass	test_click_collectionGuarantee (test.test_firstp.TestFirstp005)	验证点击页面底部 藏品保障 ，页面正确跳转

2021-06-18 16:22:07,187 8663518720    ERROR test_runner.py(195) - 
Skip	test_click_contactUs (test.test_firstp.TestFirstp005)	验证点击页面底部 联系我们 ，页面正确跳转
Error	test_click_guide (test.test_firstp.TestFirstp005)	验证点击页面底部 新手指南 ，页面正确跳转
Error	test_click_guide (test.test_firstp.TestFirstp005)	验证点击页面底部 新手指南 ，页面正确跳转
Error	test_click_serviceA (test.test_firstp.TestFirstp005)	验证点击页面底部 服务协议 ，页面正确跳转
Error	test_click_serviceA (test.test_firstp.TestFirstp005)	验证点击页面底部 服务协议 ，页面正确跳转

2021-06-18 16:22:07,189 8663518720     INFO test_runner.py(213) - 
测试结束！
运行时间: 0:00:35.790476
共计执行用例数量：6
执行成功用例数量：3
执行失败用例数量：0
跳过执行用例数量：1
产生异常用例数量：2

