2021-06-18 16:53:45,978 8665124352     INFO test_runner.py(156) - 预计并发线程数：1
2021-06-18 16:53:58,328 13066469376     INFO result.py(69) - 开始测试： test_click_searchBox001 (test.test_firstp.TestFirstp001)
2021-06-18 16:54:03,750 13066469376     INFO result.py(156) - 测试执行通过： test_click_searchBox001 (test.test_firstp.TestFirstp001)
2021-06-18 16:54:03,757 13066469376     INFO result.py(90) - 测试结束： test_click_searchBox001 (test.test_firstp.TestFirstp001)
2021-06-18 16:54:03,763 13066469376     INFO result.py(91) - 耗时： 5.428136825561523
2021-06-18 16:54:03,770 13066469376     INFO result.py(69) - 开始测试： test_click_searchBox002 (test.test_firstp.TestFirstp001)
2021-06-18 16:54:08,880 13066469376     INFO result.py(156) - 测试执行通过： test_click_searchBox002 (test.test_firstp.TestFirstp001)
2021-06-18 16:54:08,886 13066469376     INFO result.py(90) - 测试结束： test_click_searchBox002 (test.test_firstp.TestFirstp001)
2021-06-18 16:54:08,886 13066469376     INFO result.py(91) - 耗时： 5.116227865219116
2021-06-18 16:54:08,892 13066469376     INFO result.py(69) - 开始测试： test_click_searchBox003 (test.test_firstp.TestFirstp001)
2021-06-18 16:54:13,978 13066469376     INFO result.py(156) - 测试执行通过： test_click_searchBox003 (test.test_firstp.TestFirstp001)
2021-06-18 16:54:13,984 13066469376     INFO result.py(90) - 测试结束： test_click_searchBox003 (test.test_firstp.TestFirstp001)
2021-06-18 16:54:13,985 13066469376     INFO result.py(91) - 耗时： 5.0920209884643555
2021-06-18 16:54:13,985 13066469376     INFO result.py(69) - 开始测试： test_qrcode (test.test_firstp.TestFirstp001)
2021-06-18 16:54:14,013 13066469376     INFO result.py(156) - 测试执行通过： test_qrcode (test.test_firstp.TestFirstp001)
2021-06-18 16:54:14,013 13066469376     INFO result.py(90) - 测试结束： test_qrcode (test.test_firstp.TestFirstp001)
2021-06-18 16:54:14,013 13066469376     INFO result.py(91) - 耗时： 0.02854180335998535
2021-06-18 16:54:14,014 13066469376     INFO result.py(69) - 开始测试： test_searchBoxInfo (test.test_firstp.TestFirstp001)
2021-06-18 16:54:14,045 13066469376     INFO result.py(156) - 测试执行通过： test_searchBoxInfo (test.test_firstp.TestFirstp001)
2021-06-18 16:54:14,045 13066469376     INFO result.py(90) - 测试结束： test_searchBoxInfo (test.test_firstp.TestFirstp001)
2021-06-18 16:54:14,051 13066469376     INFO result.py(91) - 耗时： 0.03101181983947754
2021-06-18 16:54:14,057 13066469376     INFO result.py(69) - 开始测试： test_title (test.test_firstp.TestFirstp001)
2021-06-18 16:54:14,060 13066469376     INFO result.py(156) - 测试执行通过： test_title (test.test_firstp.TestFirstp001)
2021-06-18 16:54:14,061 13066469376     INFO result.py(90) - 测试结束： test_title (test.test_firstp.TestFirstp001)
2021-06-18 16:54:14,061 13066469376     INFO result.py(91) - 耗时： 0.0030930042266845703
2021-06-18 16:54:14,112 8665124352  WARNING connectionpool.py(304) - Connection pool is full, discarding connection: 127.0.0.1
2021-06-18 16:54:14,124 13066469376     INFO result.py(69) - 开始测试： test_url (test.test_firstp.TestFirstp001)
2021-06-18 16:54:14,124 13066469376  WARNING connectionpool.py(780) - Retrying (Retry(total=2, connect=None, read=None, redirect=None, status=None)) after connection broken by 'NewConnectionError('<urllib3.connection.HTTPConnection object at 0x10e74fdc0>: Failed to establish a new connection: [Errno 61] Connection refused')': /session/4af127671509525a3926e3f50e5d28c7/url
2021-06-18 16:54:14,125 13066469376  WARNING connectionpool.py(780) - Retrying (Retry(total=1, connect=None, read=None, redirect=None, status=None)) after connection broken by 'NewConnectionError('<urllib3.connection.HTTPConnection object at 0x10e89ddf0>: Failed to establish a new connection: [Errno 61] Connection refused')': /session/4af127671509525a3926e3f50e5d28c7/url
2021-06-18 16:54:14,125 13066469376  WARNING connectionpool.py(780) - Retrying (Retry(total=0, connect=None, read=None, redirect=None, status=None)) after connection broken by 'NewConnectionError('<urllib3.connection.HTTPConnection object at 0x10e89de80>: Failed to establish a new connection: [Errno 61] Connection refused')': /session/4af127671509525a3926e3f50e5d28c7/url
2021-06-18 16:54:14,129 13066469376    ERROR result.py(175) - 测试产生错误： test_url (test.test_firstp.TestFirstp001)
Traceback (most recent call last):
  File "/Users/yuanyuanhe/PycharmProjects/zspaimai_ui/venv/lib/python3.9/site-packages/urllib3/connection.py", line 169, in _new_conn
    conn = connection.create_connection(
  File "/Users/yuanyuanhe/PycharmProjects/zspaimai_ui/venv/lib/python3.9/site-packages/urllib3/util/connection.py", line 96, in create_connection
    raise err
  File "/Users/yuanyuanhe/PycharmProjects/zspaimai_ui/venv/lib/python3.9/site-packages/urllib3/util/connection.py", line 86, in create_connection
    sock.connect(sa)
ConnectionRefusedError: [Errno 61] Connection refused

During handling of the above exception, another exception occurred:

Traceback (most recent call last):
  File "/Users/yuanyuanhe/PycharmProjects/zspaimai_ui/venv/lib/python3.9/site-packages/urllib3/connectionpool.py", line 699, in urlopen
    httplib_response = self._make_request(
  File "/Users/yuanyuanhe/PycharmProjects/zspaimai_ui/venv/lib/python3.9/site-packages/urllib3/connectionpool.py", line 394, in _make_request
    conn.request(method, url, **httplib_request_kw)
  File "/Users/yuanyuanhe/PycharmProjects/zspaimai_ui/venv/lib/python3.9/site-packages/urllib3/connection.py", line 234, in request
    super(HTTPConnection, self).request(method, url, body=body, headers=headers)
  File "/Library/Frameworks/Python.framework/Versions/3.9/lib/python3.9/http/client.py", line 1253, in request
    self._send_request(method, url, body, headers, encode_chunked)
  File "/Library/Frameworks/Python.framework/Versions/3.9/lib/python3.9/http/client.py", line 1299, in _send_request
    self.endheaders(body, encode_chunked=encode_chunked)
  File "/Library/Frameworks/Python.framework/Versions/3.9/lib/python3.9/http/client.py", line 1248, in endheaders
    self._send_output(message_body, encode_chunked=encode_chunked)
  File "/Library/Frameworks/Python.framework/Versions/3.9/lib/python3.9/http/client.py", line 1008, in _send_output
    self.send(msg)
  File "/Library/Frameworks/Python.framework/Versions/3.9/lib/python3.9/http/client.py", line 948, in send
    self.connect()
  File "/Users/yuanyuanhe/PycharmProjects/zspaimai_ui/venv/lib/python3.9/site-packages/urllib3/connection.py", line 200, in connect
    conn = self._new_conn()
  File "/Users/yuanyuanhe/PycharmProjects/zspaimai_ui/venv/lib/python3.9/site-packages/urllib3/connection.py", line 181, in _new_conn
    raise NewConnectionError(
urllib3.exceptions.NewConnectionError: <urllib3.connection.HTTPConnection object at 0x10e8cf130>: Failed to establish a new connection: [Errno 61] Connection refused

During handling of the above exception, another exception occurred:

Traceback (most recent call last):
  File "/Users/yuanyuanhe/PycharmProjects/zspaimai_ui/test/test_firstp.py", line 14, in test_url
    self.assertEqual('http://home.online.zspaimai.cn/', self.driver.current_url)
  File "/Users/yuanyuanhe/PycharmProjects/zspaimai_ui/venv/lib/python3.9/site-packages/selenium/webdriver/remote/webdriver.py", line 669, in current_url
    return self.execute(Command.GET_CURRENT_URL)['value']
  File "/Users/yuanyuanhe/PycharmProjects/zspaimai_ui/venv/lib/python3.9/site-packages/selenium/webdriver/remote/webdriver.py", line 319, in execute
    response = self.command_executor.execute(driver_command, params)
  File "/Users/yuanyuanhe/PycharmProjects/zspaimai_ui/venv/lib/python3.9/site-packages/selenium/webdriver/remote/remote_connection.py", line 374, in execute
    return self._request(command_info[0], url, body=data)
  File "/Users/yuanyuanhe/PycharmProjects/zspaimai_ui/venv/lib/python3.9/site-packages/selenium/webdriver/remote/remote_connection.py", line 397, in _request
    resp = self._conn.request(method, url, body=body, headers=headers)
  File "/Users/yuanyuanhe/PycharmProjects/zspaimai_ui/venv/lib/python3.9/site-packages/urllib3/request.py", line 74, in request
    return self.request_encode_url(
  File "/Users/yuanyuanhe/PycharmProjects/zspaimai_ui/venv/lib/python3.9/site-packages/urllib3/request.py", line 96, in request_encode_url
    return self.urlopen(method, url, **extra_kw)
  File "/Users/yuanyuanhe/PycharmProjects/zspaimai_ui/venv/lib/python3.9/site-packages/urllib3/poolmanager.py", line 375, in urlopen
    response = conn.urlopen(method, u.request_uri, **kw)
  File "/Users/yuanyuanhe/PycharmProjects/zspaimai_ui/venv/lib/python3.9/site-packages/urllib3/connectionpool.py", line 783, in urlopen
    return self.urlopen(
  File "/Users/yuanyuanhe/PycharmProjects/zspaimai_ui/venv/lib/python3.9/site-packages/urllib3/connectionpool.py", line 783, in urlopen
    return self.urlopen(
  File "/Users/yuanyuanhe/PycharmProjects/zspaimai_ui/venv/lib/python3.9/site-packages/urllib3/connectionpool.py", line 783, in urlopen
    return self.urlopen(
  File "/Users/yuanyuanhe/PycharmProjects/zspaimai_ui/venv/lib/python3.9/site-packages/urllib3/connectionpool.py", line 755, in urlopen
    retries = retries.increment(
  File "/Users/yuanyuanhe/PycharmProjects/zspaimai_ui/venv/lib/python3.9/site-packages/urllib3/util/retry.py", line 574, in increment
    raise MaxRetryError(_pool, url, error or ResponseError(cause))
urllib3.exceptions.MaxRetryError: HTTPConnectionPool(host='127.0.0.1', port=63989): Max retries exceeded with url: /session/4af127671509525a3926e3f50e5d28c7/url (Caused by NewConnectionError('<urllib3.connection.HTTPConnection object at 0x10e8cf130>: Failed to establish a new connection: [Errno 61] Connection refused'))

2021-06-18 16:54:14,129 13066469376     INFO result.py(90) - 测试结束： test_url (test.test_firstp.TestFirstp001)
2021-06-18 16:54:14,129 13066469376     INFO result.py(91) - 耗时： 0.005475044250488281
2021-06-18 16:54:14,130 8665124352     INFO test_runner.py(193) - 
Pass	test_click_searchBox001 (test.test_firstp.TestFirstp001)	验证点击搜索框，显示搜索历史框
Pass	test_click_searchBox002 (test.test_firstp.TestFirstp001)	验证点击搜索框，历史框包含搜索历史文本
Pass	test_click_searchBox003 (test.test_firstp.TestFirstp001)	验证点击搜索框，历史框包含删除按钮
Pass	test_qrcode (test.test_firstp.TestFirstp001)	验证页面底部显示 中晟在线 二维码
Pass	test_searchBoxInfo (test.test_firstp.TestFirstp001)	验证搜索框的提示文本信息为： 藏品名称
Pass	test_title (test.test_firstp.TestFirstp001)	验证首页标题

2021-06-18 16:54:14,130 8665124352    ERROR test_runner.py(195) - 
Error	test_url (test.test_firstp.TestFirstp001)	验证首页网址

2021-06-18 16:54:14,130 8665124352     INFO test_runner.py(213) - 
测试结束！
运行时间: 0:00:28.322411
共计执行用例数量：7
执行成功用例数量：6
执行失败用例数量：0
跳过执行用例数量：0
产生异常用例数量：1

